Workbook
Name _Hlk69890696: 'ข้อยกเว้น CI 123'!$A$15
Name _Hlk69890696: 'ข้อยกเว้น Roke Rai So Shield'!$A$28
Name _Hlk69890696: 'เงื่อนไขที่สำคัญ ข้อยกเว้น iHU'!$A$34
Name _Hlk69890696: 'เงื่อนไขที่สำคัญ ข้อยกเว้น MEX'!$A$36
Name _Hlk69890696: 'นิยามโรค Roke Rai So Shield'!$B$29
Name _Hlk69890696: 'รายชื่อโรค CI 123'!$A$65
Name _Hlk72091284: 'ผลประโยชน์ โรคร้ายโซชิลด์'!$A$9
Name _Hlk72091284: 'ผลประโยชน์ ไอเฮลท์ตี้ อัลตร้า'!$A$6
Name _Hlk72676939: 'ผลประโยชน์ โรคร้ายโซชิลด์'!$A$54
Name _Hlk72676939: 'ผลประโยชน์ ไอเฮลท์ตี้ อัลตร้า'!$A$63
Name _Hlk72824934: 'ผลประโยชน์ โรคร้ายโซชิลด์'!#REF!
Name _Hlk72824934: 'ผลประโยชน์ ไอเฮลท์ตี้ อัลตร้า'!#REF!
Name _Hlk72839288: 'ผลประโยชน์ โรคร้ายโซชิลด์'!#REF!
Name _Hlk72839288: 'ผลประโยชน์ ไอเฮลท์ตี้ อัลตร้า'!#REF!
Name _Toc98510358: กรอกข้อมูล!$A$85
Name a: '[1]Global Assumption'!$D$13
Name a: '[1]Global Assumption'!$D$13
Name a: '[1]Global Assumption'!$D$13
Name a: '[2]Global Assumption'!$D$13
Name a: '[2]Global Assumption'!$D$13
Name a: '[2]Global Assumption'!$D$13
Name a: '[2]Global Assumption'!$D$13
Name aa: [1]PremiumReport!$A$2
Name aa: [1]PremiumReport!$A$2
Name aa: [1]PremiumReport!$A$2
Name aa: [2]PremiumReport!$A$2
Name aa: [2]PremiumReport!$A$2
Name aa: [2]PremiumReport!$A$2
Name aa: [2]PremiumReport!$A$2
Name age: '[1]Global Assumption'!$D$13
Name age: '[1]Global Assumption'!$D$13
Name age: '[1]Global Assumption'!$D$13
Name age: '[2]Global Assumption'!$D$13
Name age: '[2]Global Assumption'!$D$13
Name age: '[2]Global Assumption'!$D$13
Name age: '[2]Global Assumption'!$D$13
Name BuyOnly: [3]กรอกข้อมูล!#REF!
Name BuyOnly: [4]กรอกข้อมูล!#REF!
Name BuyOnly: [4]กรอกข้อมูล!#REF!
Name BuyOnly: [3]กรอกข้อมูล!#REF!
Name BuyOnly: [3]กรอกข้อมูล!#REF!
Name BuyOnly: [4]กรอกข้อมูล!#REF!
Name BuyOnly: [3]กรอกข้อมูล!#REF!
Name BuyOnly: [4]กรอกข้อมูล!#REF!
Name BuyOnly: กรอกข้อมูล!#REF!
Name CannotBuy: [3]กรอกข้อมูล!#REF!
Name CannotBuy: [4]กรอกข้อมูล!#REF!
Name CannotBuy: [4]กรอกข้อมูล!#REF!
Name CannotBuy: [3]กรอกข้อมูล!#REF!
Name CannotBuy: [3]กรอกข้อมูล!#REF!
Name CannotBuy: [4]กรอกข้อมูล!#REF!
Name CannotBuy: [3]กรอกข้อมูล!#REF!
Name CannotBuy: [4]กรอกข้อมูล!#REF!
Name CannotBuy: กรอกข้อมูล!#REF!
Name CVAge: [5]CVCalculation!$C$2
Name CVAge: [5]CVCalculation!$C$2
Name CVAge: [5]CVCalculation!$C$2
Name CVAge: [6]CVCalculation!$C$2
Name CVAge: [6]CVCalculation!$C$2
Name CVAge: [6]CVCalculation!$C$2

Sheet WPD01
A1: ตารางแสดงอัตราเบี้ยประกันภัย
A2: สัญญาเพิ่มเติมผลประโยชน์ผู้ชำระเบี้ยประกันภัย (WPD01)
A3: ต่อเบี้ยประกันภัย 100 บาท
D5: ระยะเวลายกเว้นเบี้ยประกันภัย (ปี)
A6: age | B6: sex | D6: 10 | E6: 11 | F6: 12 | G6: 13 | H6: 14 | I6: 15 | J6: 16 | K6: 17 | L6: 18 | M6: 19 | N6: 20 | O6: 21 | P6: 22 | Q6: 23 | R6: 24 | S6: 25
A7: 20 | B7: Male | C7: =A7&"-"&LEFT(B7,1) -> 20-M | D7: 1.33 | E7: 1.48 | F7: 1.63 | G7: 1.77 | H7: 1.92 | I7: 2.07 | J7: 2.22 | K7: 2.37 | L7: 2.52 | M7: 2.67 | N7: 2.82 | O7: 2.98 | P7: 3.14 | Q7: 3.3 | R7: 3.47 | S7: 3.63
A8: 21 | B8: Male | C8: =A8&"-"&LEFT(B8,1) -> 21-M | D8: 1.36 | E8: 1.51 | F8: 1.66 | G8: 1.8 | H8: 1.95 | I8: 2.1 | J8: 2.25 | K8: 2.41 | L8: 2.56 | M8: 2.72 | N8: 2.87 | O8: 3.04 | P8: 3.2 | Q8: 3.37 | R8: 3.54 | S8: 3.72
A9: 22 | B9: Male | C9: =A9&"-"&LEFT(B9,1) -> 22-M | D9: 1.37 | E9: 1.52 | F9: 1.67 | G9: 1.83 | H9: 1.98 | I9: 2.13 | J9: 2.28 | K9: 2.44 | L9: 2.6 | M9: 2.76 | N9: 2.92 | O9: 3.09 | P9: 3.26 | Q9: 3.43 | R9: 3.61 | S9: 3.79
A10: 23 | B10: Male | C10: =A10&"-"&LEFT(B10,1) -> 23-M | D10: 1.38 | E10: 1.54 | F10: 1.69 | G10: 1.84 | H10: 1.99 | I10: 2.15 | J10: 2.31 | K10: 2.47 | L10: 2.63 | M10: 2.8 | N10: 2.96 | O10: 3.14 | P10: 3.31 | Q10: 3.5 | R10: 3.68 | S10: 3.88
A11: 24 | B11: Male | C11: =A11&"-"&LEFT(B11,1) -> 24-M | D11: 1.39 | E11: 1.54 | F11: 1.7 | G11: 1.85 | H11: 2.01 | I11: 2.17 | J11: 2.33 | K11: 2.5 | L11: 2.66 | M11: 2.84 | N11: 3.01 | O11: 3.19 | P11: 3.38 | Q11: 3.57 | R11: 3.76 | S11: 3.97
A12: 25 | B12: Male | C12: =A12&"-"&LEFT(B12,1) -> 25-M | D12: 1.4 | E12: 1.55 | F12: 1.71 | G12: 1.87 | H12: 2.03 | I12: 2.19 | J12: 2.36 | K12: 2.53 | L12: 2.71 | M12: 2.88 | N12: 3.07 | O12: 3.26 | P12: 3.45 | Q12: 3.65 | R12: 3.86 | S12: 4.07
A13: 26 | B13: Male | C13: =A13&"-"&LEFT(B13,1) -> 26-M | D13: 1.41 | E13: 1.57 | F13: 1.73 | G13: 1.89 | H13: 2.05 | I13: 2.22 | J13: 2.4 | K13: 2.57 | L13: 2.76 | M13: 2.94 | N13: 3.13 | O13: 3.33 | P13: 3.54 | Q13: 3.74 | R13: 3.96 | S13: 4.18
A14: 27 | B14: Male | C14: =A14&"-"&LEFT(B14,1) -> 27-M | D14: 1.42 | E14: 1.58 | F14: 1.75 | G14: 1.91 | H14: 2.09 | I14: 2.26 | J14: 2.44 | K14: 2.63 | L14: 2.82 | M14: 3.01 | N14: 3.21 | O14: 3.42 | P14: 3.63 | Q14: 3.85 | R14: 4.08 | S14: 4.32
A15: 28 | B15: Male | C15: =A15&"-"&LEFT(B15,1) -> 28-M | D15: 1.44 | E15: 1.6 | F15: 1.77 | G15: 1.95 | H15: 2.13 | I15: 2.31 | J15: 2.5 | K15: 2.69 | L15: 2.89 | M15: 3.1 | N15: 3.31 | O15: 3.53 | P15: 3.75 | Q15: 3.98 | R15: 4.23 | S15: 4.48
A16: 29 | B16: Male | C16: =A16&"-"&LEFT(B16,1) -> 29-M | D16: 1.46 | E16: 1.63 | F16: 1.81 | G16: 1.99 | H16: 2.18 | I16: 2.37 | J16: 2.57 | K16: 2.77 | L16: 2.98 | M16: 3.2 | N16: 3.42 | O16: 3.65 | P16: 3.89 | Q16: 4.13 | R16: 4.39 | S16: 4.66
A17: 30 | B17: Male | C17: =A17&"-"&LEFT(B17,1) -> 30-M | D17: 1.49 | E17: 1.67 | F17: 1.86 | G17: 2.05 | H17: 2.24 | I17: 2.44 | J17: 2.65 | K17: 2.87 | L17: 3.09 | M17: 3.31 | N17: 3.55 | O17: 3.79 | P17: 4.04 | Q17: 4.31 | R17: 4.58 | S17: 4.86
A18: 31 | B18: Male | C18: =A18&"-"&LEFT(B18,1) -> 31-M | D18: 1.53 | E18: 1.72 | F18: 1.92 | G18: 2.11 | H18: 2.32 | I18: 2.53 | J18: 2.75 | K18: 2.98 | L18: 3.21 | M18: 3.45 | N18: 3.7 | O18: 3.96 | P18: 4.22 | Q18: 4.5 | R18: 4.8 | S18: 5.1
... A41: 54 | B41: Male | C41: =A41&"-"&LEFT(B41,1) -> 54-M | D41: 6.79 | E41: 7.81 | F41: 0 | G41: 0 | H41: 0 | I41: 0 | J41: 0 | K41: 0 | L41: 0 | M41: 0 | N41: 0 | O41: 0 | P41: 0 | Q41: 0 | R41: 0 | S41: 0
A42: 55 | B42: Male | C42: =A42&"-"&LEFT(B42,1) -> 55-M | D42: 7.48 | E42: 0 | F42: 0 | G42: 0 | H42: 0 | I42: 0 | J42: 0 | K42: 0
A43: 20 | B43: Female | C43: =A43&"-"&LEFT(B43,1) -> 20-F | D43: 0.44 | E43: 0.49 | F43: 0.54 | G43: 0.59 | H43: 0.65 | I43: 0.7 | J43: 0.75 | K43: 0.81 | L43: 0.86 | M43: 0.92 | N43: 0.98 | O43: 1.04 | P43: 1.1 | Q43: 1.17 | R43: 1.23 | S43: 1.3
A44: 21 | B44: Female | C44: =A44&"-"&LEFT(B44,1) -> 21-F | D44: 0.45 | E44: 0.5 | F44: 0.55 | G44: 0.61 | H44: 0.66 | I44: 0.72 | J44: 0.77 | K44: 0.83 | L44: 0.89 | M44: 0.95 | N44: 1.01 | O44: 1.07 | P44: 1.13 | Q44: 1.2 | R44: 1.27 | S44: 1.34
A45: 22 | B45: Female | C45: =A45&"-"&LEFT(B45,1) -> 22-F | D45: 0.46 | E45: 0.51 | F45: 0.57 | G45: 0.62 | H45: 0.68 | I45: 0.73 | J45: 0.79 | K45: 0.85 | L45: 0.91 | M45: 0.97 | N45: 1.04 | O45: 1.1 | P45: 1.17 | Q45: 1.24 | R45: 1.31 | S45: 1.38
A46: 23 | B46: Female | C46: =A46&"-"&LEFT(B46,1) -> 23-F | D46: 0.47 | E46: 0.52 | F46: 0.58 | G46: 0.63 | H46: 0.69 | I46: 0.75 | J46: 0.81 | K46: 0.87 | L46: 0.94 | M46: 1 | N46: 1.07 | O46: 1.14 | P46: 1.21 | Q46: 1.28 | R46: 1.35 | S46: 1.43
A47: 24 | B47: Female | C47: =A47&"-"&LEFT(B47,1) -> 24-F | D47: 0.48 | E47: 0.53 | F47: 0.59 | G47: 0.65 | H47: 0.71 | I47: 0.77 | J47: 0.84 | K47: 0.9 | L47: 0.97 | M47: 1.03 | N47: 1.1 | O47: 1.18 | P47: 1.25 | Q47: 1.32 | R47: 1.4 | S47: 1.48
A48: 25 | B48: Female | C48: =A48&"-"&LEFT(B48,1) -> 25-F | D48: 0.49 | E48: 0.55 | F48: 0.61 | G48: 0.67 | H48: 0.73 | I48: 0.8 | J48: 0.86 | K48: 0.93 | L48: 1 | M48: 1.07 | N48: 1.14 | O48: 1.22 | P48: 1.29 | Q48: 1.37 | R48: 1.45 | S48: 1.54
A49: 26 | B49: Female | C49: =A49&"-"&LEFT(B49,1) -> 26-F | D49: 0.5 | E49: 0.56 | F49: 0.63 | G49: 0.69 | H49: 0.75 | I49: 0.82 | J49: 0.89 | K49: 0.96 | L49: 1.03 | M49: 1.11 | N49: 1.18 | O49: 1.26 | P49: 1.34 | Q49: 1.43 | R49: 1.51 | S49: 1.6
A50: 27 | B50: Female | C50: =A50&"-"&LEFT(B50,1) -> 27-F | D50: 0.52 | E50: 0.58 | F50: 0.65 | G50: 0.71 | H50: 0.78 | I50: 0.85 | J50: 0.93 | K50: 1 | L50: 1.07 | M50: 1.15 | N50: 1.23 | O50: 1.31 | P50: 1.4 | Q50: 1.49 | R50: 1.58 | S50: 1.68
A51: 28 | B51: Female | C51: =A51&"-"&LEFT(B51,1) -> 28-F | D51: 0.54 | E51: 0.6 | F51: 0.67 | G51: 0.74 | H51: 0.81 | I51: 0.89 | J51: 0.96 | K51: 1.04 | L51: 1.12 | M51: 1.2 | N51: 1.28 | O51: 1.37 | P51: 1.46 | Q51: 1.56 | R51: 1.66 | S51: 1.76
A52: 29 | B52: Female | C52: =A52&"-"&LEFT(B52,1) -> 29-F | D52: 0.56 | E52: 0.63 | F52: 0.7 | G52: 0.77 | H52: 0.85 | I52: 0.93 | J52: 1 | K52: 1.09 | L52: 1.17 | M52: 1.25 | N52: 1.34 | O52: 1.44 | P52: 1.53 | Q52: 1.63 | R52: 1.74 | S52: 1.85
A53: 30 | B53: Female | C53: =A53&"-"&LEFT(B53,1) -> 30-F | D53: 0.58 | E53: 0.66 | F53: 0.73 | G53: 0.81 | H53: 0.89 | I53: 0.97 | J53: 1.05 | K53: 1.14 | L53: 1.22 | M53: 1.31 | N53: 1.41 | O53: 1.51 | P53: 1.61 | Q53: 1.72 | R53: 1.83 | S53: 1.96
A54: 31 | B54: Female | C54: =A54&"-"&LEFT(B54,1) -> 31-F | D54: 0.61 | E54: 0.69 | F54: 0.77 | G54: 0.85 | H54: 0.93 | I54: 1.01 | J54: 1.1 | K54: 1.19 | L54: 1.28 | M54: 1.38 | N54: 1.48 | O54: 1.59 | P54: 1.7 | Q54: 1.82 | R54: 1.94 | S54: 2.07
... A78: 55 | B78: Female | C78: =A78&"-"&LEFT(B78,1) -> 55-F | D78: 4.17 | E78: 0 | F78: 0 | G78: 0 | H78: 0 | I78: 0 | J78: 0 | K78: 0 | L78: 0 | M78: 0 | N78: 0 | O78: 0 | P78: 0 | Q78: 0 | R78: 0 | S78: 0

Sheet WPDD01
A1: ตารางแสดงอัตราเบี้ยประกันภัย
A2: สัญญาเพิ่มเติมผลประโยชน์ผู้ชำระเบี้ยประกันภัย (WPDD01)
A3: ต่อเบี้ยประกันภัย 100 บาท
D5: ระยะเวลายกเว้นเบี้ยประกันภัย (ปี)
A6: age | B6: sex | D6: 10 | E6: 11 | F6: 12 | G6: 13 | H6: 14 | I6: 15 | J6: 16 | K6: 17 | L6: 18 | M6: 19 | N6: 20 | O6: 21 | P6: 22 | Q6: 23 | R6: 24 | S6: 25
A7: 20 | B7: Male | C7: =A7&"-"&LEFT(B7,1) -> 20-M | D7: 1.53 | E7: 1.7 | F7: 1.87 | G7: 2.04 | H7: 2.21 | I7: 2.38 | J7: 2.55 | K7: 2.72 | L7: 2.9 | M7: 3.07 | N7: 3.25 | O7: 3.43 | P7: 3.61 | Q7: 3.8 | R7: 3.99 | S7: 4.18
A8: 21 | B8: Male | C8: =A8&"-"&LEFT(B8,1) -> 21-M | D8: 1.56 | E8: 1.73 | F8: 1.9 | G8: 2.08 | H8: 2.25 | I8: 2.42 | J8: 2.59 | K8: 2.77 | L8: 2.95 | M8: 3.13 | N8: 3.31 | O8: 3.49 | P8: 3.68 | Q8: 3.88 | R8: 4.07 | S8: 4.28
A9: 22 | B9: Male | C9: =A9&"-"&LEFT(B9,1) -> 22-M | D9: 1.58 | E9: 1.75 | F9: 1.93 | G9: 2.1 | H9: 2.27 | I9: 2.45 | J9: 2.63 | K9: 2.81 | L9: 2.99 | M9: 3.17 | N9: 3.36 | O9: 3.55 | P9: 3.75 | Q9: 3.95 | R9: 4.16 | S9: 4.37
A10: 23 | B10: Male | C10: =A10&"-"&LEFT(B10,1) -> 23-M | D10: 1.59 | E10: 1.77 | F10: 1.94 | G10: 2.12 | H10: 2.3 | I10: 2.47 | J10: 2.66 | K10: 2.84 | L10: 3.03 | M10: 3.22 | N10: 3.41 | O10: 3.61 | P10: 3.81 | Q10: 4.02 | R10: 4.24 | S10: 4.46
A11: 24 | B11: Male | C11: =A11&"-"&LEFT(B11,1) -> 24-M | D11: 1.6 | E11: 1.78 | F11: 1.95 | G11: 2.13 | H11: 2.31 | I11: 2.5 | J11: 2.68 | K11: 2.87 | L11: 3.07 | M11: 3.26 | N11: 3.47 | O11: 3.67 | P11: 3.89 | Q11: 4.11 | R11: 4.33 | S11: 4.57
A12: 25 | B12: Male | C12: =A12&"-"&LEFT(B12,1) -> 25-M | D12: 1.61 | E12: 1.79 | F12: 1.97 | G12: 2.15 | H12: 2.34 | I12: 2.52 | J12: 2.72 | K12: 2.91 | L12: 3.11 | M12: 3.32 | N12: 3.53 | O12: 3.75 | P12: 3.97 | Q12: 4.2 | R12: 4.44 | S12: 4.68
A13: 26 | B13: Male | C13: =A13&"-"&LEFT(B13,1) -> 26-M | D13: 1.62 | E13: 1.8 | F13: 1.99 | G13: 2.17 | H13: 2.36 | I13: 2.56 | J13: 2.76 | K13: 2.96 | L13: 3.17 | M13: 3.39 | N13: 3.61 | O13: 3.83 | P13: 4.07 | Q13: 4.31 | R13: 4.56 | S13: 4.82
A14: 27 | B14: Male | C14: =A14&"-"&LEFT(B14,1) -> 27-M | D14: 1.63 | E14: 1.82 | F14: 2.01 | G14: 2.2 | H14: 2.4 | I14: 2.6 | J14: 2.81 | K14: 3.02 | L14: 3.24 | M14: 3.47 | N14: 3.7 | O14: 3.94 | P14: 4.18 | Q14: 4.44 | R14: 4.7 | S14: 4.97
A15: 28 | B15: Male | C15: =A15&"-"&LEFT(B15,1) -> 28-M | D15: 1.65 | E15: 1.85 | F15: 2.04 | G15: 2.24 | H15: 2.45 | I15: 2.66 | J15: 2.87 | K15: 3.1 | L15: 3.33 | M15: 3.56 | N15: 3.81 | O15: 4.06 | P15: 4.32 | Q15: 4.59 | R15: 4.86 | S15: 5.15
A16: 29 | B16: Male | C16: =A16&"-"&LEFT(B16,1) -> 29-M | D16: 1.68 | E16: 1.88 | F16: 2.08 | G16: 2.29 | H16: 2.51 | I16: 2.73 | J16: 2.95 | K16: 3.19 | L16: 3.43 | M16: 3.68 | N16: 3.93 | O16: 4.2 | P16: 4.47 | Q16: 4.76 | R16: 5.05 | S16: 5.36
A17: 30 | B17: Male | C17: =A17&"-"&LEFT(B17,1) -> 30-M | D17: 1.72 | E17: 1.93 | F17: 2.14 | G17: 2.36 | H17: 2.58 | I17: 2.81 | J17: 3.05 | K17: 3.3 | L17: 3.55 | M17: 3.81 | N17: 4.08 | O17: 4.36 | P17: 4.65 | Q17: 4.96 | R17: 5.27 | S17: 5.6
A18: 31 | B18: Male | C18: =A18&"-"&LEFT(B18,1) -> 31-M | D18: 1.77 | E18: 1.98 | F18: 2.2 | G18: 2.43 | H18: 2.67 | I18: 2.91 | J18: 3.17 | K18: 3.42 | L18: 3.69 | M18: 3.97 | N18: 4.25 | O18: 4.55 | P18: 4.86 | Q18: 5.18 | R18: 5.52 | S18: 5.87
... A41: 54 | B41: Male | C41: =A41&"-"&LEFT(B41,1) -> 54-M | D41: 7.81 | E41: 8.99 | F41: 0 | G41: 0 | H41: 0 | I41: 0 | J41: 0 | K41: 0 | L41: 0 | M41: 0 | N41: 0 | O41: 0 | P41: 0 | Q41: 0 | R41: 0 | S41: 0
A42: 55 | B42: Male | C42: =A42&"-"&LEFT(B42,1) -> 55-M | D42: 8.61
A43: 20 | B43: Female | C43: =A43&"-"&LEFT(B43,1) -> 20-F | D43: 0.51 | E43: 0.57 | F43: 0.62 | G43: 0.68 | H43: 0.74 | I43: 0.8 | J43: 0.87 | K43: 0.93 | L43: 0.99 | M43: 1.06 | N43: 1.13 | O43: 1.2 | P43: 1.27 | Q43: 1.34 | R43: 1.41 | S43: 1.49
A44: 21 | B44: Female | C44: =A44&"-"&LEFT(B44,1) -> 21-F | D44: 0.52 | E44: 0.58 | F44: 0.64 | G44: 0.7 | H44: 0.76 | I44: 0.82 | J44: 0.89 | K44: 0.95 | L44: 1.02 | M44: 1.09 | N44: 1.16 | O44: 1.23 | P44: 1.31 | Q44: 1.38 | R44: 1.46 | S44: 1.54
A45: 22 | B45: Female | C45: =A45&"-"&LEFT(B45,1) -> 22-F | D45: 0.53 | E45: 0.59 | F45: 0.65 | G45: 0.71 | H45: 0.78 | I45: 0.84 | J45: 0.91 | K45: 0.98 | L45: 1.05 | M45: 1.12 | N45: 1.19 | O45: 1.27 | P45: 1.35 | Q45: 1.42 | R45: 1.5 | S45: 1.59
A46: 23 | B46: Female | C46: =A46&"-"&LEFT(B46,1) -> 23-F | D46: 0.54 | E46: 0.6 | F46: 0.66 | G46: 0.73 | H46: 0.8 | I46: 0.86 | J46: 0.93 | K46: 1.01 | L46: 1.08 | M46: 1.15 | N46: 1.23 | O46: 1.31 | P46: 1.39 | Q46: 1.47 | R46: 1.56 | S46: 1.64
A47: 24 | B47: Female | C47: =A47&"-"&LEFT(B47,1) -> 24-F | D47: 0.55 | E47: 0.61 | F47: 0.68 | G47: 0.75 | H47: 0.82 | I47: 0.89 | J47: 0.96 | K47: 1.04 | L47: 1.11 | M47: 1.19 | N47: 1.27 | O47: 1.35 | P47: 1.44 | Q47: 1.52 | R47: 1.61 | S47: 1.7
A48: 25 | B48: Female | C48: =A48&"-"&LEFT(B48,1) -> 25-F | D48: 0.56 | E48: 0.63 | F48: 0.7 | G48: 0.77 | H48: 0.84 | I48: 0.92 | J48: 0.99 | K48: 1.07 | L48: 1.15 | M48: 1.23 | N48: 1.31 | O48: 1.4 | P48: 1.49 | Q48: 1.58 | R48: 1.67 | S48: 1.77
A49: 26 | B49: Female | C49: =A49&"-"&LEFT(B49,1) -> 26-F | D49: 0.58 | E49: 0.65 | F49: 0.72 | G49: 0.79 | H49: 0.87 | I49: 0.95 | J49: 1.03 | K49: 1.11 | L49: 1.19 | M49: 1.28 | N49: 1.36 | O49: 1.45 | P49: 1.55 | Q49: 1.64 | R49: 1.74 | S49: 1.84
A50: 27 | B50: Female | C50: =A50&"-"&LEFT(B50,1) -> 27-F | D50: 0.59 | E50: 0.67 | F50: 0.74 | G50: 0.82 | H50: 0.9 | I50: 0.98 | J50: 1.06 | K50: 1.15 | L50: 1.24 | M50: 1.33 | N50: 1.42 | O50: 1.51 | P50: 1.61 | Q50: 1.71 | R50: 1.82 | S50: 1.93
A51: 28 | B51: Female | C51: =A51&"-"&LEFT(B51,1) -> 28-F | D51: 0.62 | E51: 0.69 | F51: 0.77 | G51: 0.85 | H51: 0.94 | I51: 1.02 | J51: 1.11 | K51: 1.2 | L51: 1.29 | M51: 1.38 | N51: 1.48 | O51: 1.58 | P51: 1.68 | Q51: 1.79 | R51: 1.9 | S51: 2.02
A52: 29 | B52: Female | C52: =A52&"-"&LEFT(B52,1) -> 29-F | D52: 0.64 | E52: 0.72 | F52: 0.8 | G52: 0.89 | H52: 0.98 | I52: 1.06 | J52: 1.15 | K52: 1.25 | L52: 1.34 | M52: 1.44 | N52: 1.55 | O52: 1.65 | P52: 1.76 | Q52: 1.88 | R52: 2 | S52: 2.13
A53: 30 | B53: Female | C53: =A53&"-"&LEFT(B53,1) -> 30-F | D53: 0.67 | E53: 0.75 | F53: 0.84 | G53: 0.93 | H53: 1.02 | I53: 1.11 | J53: 1.21 | K53: 1.31 | L53: 1.41 | M53: 1.51 | N53: 1.62 | O53: 1.73 | P53: 1.85 | Q53: 1.98 | R53: 2.11 | S53: 2.25
A54: 31 | B54: Female | C54: =A54&"-"&LEFT(B54,1) -> 31-F | D54: 0.7 | E54: 0.79 | F54: 0.88 | G54: 0.97 | H54: 1.07 | I54: 1.16 | J54: 1.26 | K54: 1.37 | L54: 1.48 | M54: 1.59 | N54: 1.7 | O54: 1.83 | P54: 1.95 | Q54: 2.09 | R54: 2.23 | S54: 2.39
... A78: 55 | B78: Female | C78: =A78&"-"&LEFT(B78,1) -> 55-F | D78: 4.79 | E78: 0 | F78: 0 | G78: 0 | H78: 0 | I78: 0 | J78: 0 | K78: 0 | L78: 0 | M78: 0 | N78: 0 | O78: 0 | P78: 0 | Q78: 0 | R78: 0 | S78: 0

Sheet Rate Rider
A1: MEB | I1: MEA+ | V1: Rate DCI,PLS
J2: ข้อมูล | K2: plan | W2: age | Y2: M | Z2: F | AC2: AP | AD2: ECARE | AG2: ผลประโยชน์ | AH2: 1000 | AI2: 2200 | AJ2: 3200 | AK2: 4200 | AL2: 6200
A3: ผลรวมของ rate | B3: plan | J3: ผลรวมของ Male | O3: ผลรวมของ Female | AB3: 1 | AC3: 3 | AD3: 6.5 | AG3: 6.1 ค่าห้อง ค่าอาหาร และค่าบริการพยาบาลประจำวันในโรงพยาบาลต่อวัน (สูงสุด 75 วัน) | AH3: 1000 | AI3: 2200 | AJ3: 3200 | AK3: 4200 | AL3: 6200
A4: ageMin | B4: 500 | C4: 1000 | D4: 2000 | E4: 3000 | F4: 4000 | G4: 5000 | I4: ageMin | J4: M-1000 | K4: M-2200 | L4: M-3200 | M4: M-4200 | N4: M-6200 | O4: F-1000 | P4: F-2200 | Q4: F-3200 | R4: F-4200 | S4: F-6200 | AB4: 2 | AC4: 4.05 | AD4: 7.5 | AG4: 6.2 ค่าห้อง ไอ ซี ยู ต่อวัน (สูงสุด 20 วัน) โดยจำนวนวันในข้อ (6.1)+(6.2) สูงสุดไม่เกิน 75 วัน | AH4: 2000 | AI4: 4400 | AJ4: 6400 | AK4: 8400 | AL4: 12400
A5: 6 | B5: 475 | C5: 950 | D5: 0 | E5: 0 | F5: 0 | G5: 0 | I5: 0 | J5: 10631 | K5: 16683 | L5: 22437 | M5: 26774 | N5: 34740 | O5: 10631 | P5: 16683 | Q5: 22437 | R5: 26774 | S5: 34740 | AB5: 3 | AC5: 5.1 | AD5: 8.5 | AG5: 6.3 ค่าแพทย์ตรวจรักษาในโรงพยาบาลประจำวันต่อวัน (สูงสุด 75 วัน) | AH5: 600 | AI5: 800 | AJ5: 900 | AK5: 1000 | AL5: 1200
A6: 7 | B6: 475 | C6: 950 | D6: 0 | E6: 0 | F6: 0 | G6: 0 | I6: 1 | J6: 10631 | K6: 16683 | L6: 22437 | M6: 26774 | N6: 34740 | O6: 10631 | P6: 16683 | Q6: 22437 | R6: 26774 | S6: 34740 | AB6: 4 | AC6: 6 | AD6: 10.5 | AG6: 6.4 ค่าปรึกษาแพทย์เฉพาะทางในโรงพยาบาล ต่อการปรึกษาแต่ละครั้ง (1 ครั้งต่อวัน สูงสุด 20 ครั้งต่อปี) | AH6: 900 | AI6: 1200 | AJ6: 1300 | AK6: 1400 | AL6: 1600
A7: 8 | B7: 475 | C7: 950 | D7: 0 | E7: 0 | F7: 0 | G7: 0 | I7: 2 | J7: 10631 | K7: 16683 | L7: 22437 | M7: 26774 | N7: 34740 | O7: 10631 | P7: 16683 | Q7: 22437 | R7: 26774 | S7: 34740 | AG7: 6.5 ค่าแพทย์ผ่าตัดและหัตถการ ต่อการเข้าพักรักษาตัวครั้งใดครั้งหนึ่ง | AH7: 40000 | AI7: 65000 | AJ7: 85000 | AK7: 100000 | AL7: 120000
A8: 9 | B8: 475 | C8: 950 | D8: 0 | E8: 0 | F8: 0 | G8: 0 | I8: 3 | J8: 10631 | K8: 16683 | L8: 22437 | M8: 26774 | N8: 34740 | O8: 10631 | P8: 16683 | Q8: 22437 | R8: 26774 | S8: 34740 | AG8: (เป็นไปตามอัตราที่กำหนดในตารางผลประโยชน์ผ่าตัด/วางยาสลบ แนบท้ายกรมธรรม์)
A9: 10 | B9: 475 | C9: 950 | D9: 0 | E9: 0 | F9: 0 | G9: 0 | I9: 4 | J9: 10631 | K9: 16683 | L9: 22437 | M9: 26774 | N9: 34740 | O9: 10631 | P9: 16683 | Q9: 22437 | R9: 26774 | S9: 34740 | AG9: - รับเพิ่ม 70% ของค่าใช้จ่ายส่วนที่เกินสิทธิ ในอัตราที่กำหนดในตารางผลประโยชน์ผ่าตัด ตามเงื่อนไขของกรมธรรม์ (กรณีค่าใช้จ่ายรวมทั้งหมดไม่เกินผลประโยชน์สูงสุดของแต่ละแผน)
A10: 11 | B10: 475 | C10: 950 | D10: 0 | E10: 0 | F10: 0 | G10: 0 | I10: 5 | J10: 10631 | K10: 16683 | L10: 22437 | M10: 26774 | N10: 34740 | O10: 10631 | P10: 16683 | Q10: 22437 | R10: 26774 | S10: 34740 | AG10: 6.6 ค่าแพทย์วิสัญญี ต่อการเข้าพักรักษาตัวครั้งใดครั้งหนึ่ง (ตามอัตราที่กำหนดในตารางค่าผ่าตัด / วางยาสลบ แนบท้ายกรมธรรม์) | AH10: 6750 | AI10: 9750 | AJ10: 13500 | AK10: 15000 | AL10: 18000
A11: 12 | B11: 475 | C11: 950 | D11: 0 | E11: 0 | F11: 0 | G11: 0 | I11: 6 | J11: 5893 | K11: 9248 | L11: 12438 | M11: 14842 | N11: 19258 | O11: 5893 | P11: 9248 | Q11: 12438 | R11: 14842 | S11: 19258 | AG11: 6.7 ค่าห้องผ่าตัดและอุปกรณ์ในห้องผ่าตัด ต่อการเข้าพักรักษาตัวใดครั้งหนึ่ง | AH11: 13500 | AI11: 19500 | AJ11: 27000 | AK11: 30000 | AL11: 36000
A12: 13 | B12: 475 | C12: 950 | D12: 0 | E12: 0 | F12: 0 | G12: 0 | I12: 7 | J12: 5893 | K12: 9248 | L12: 12438 | M12: 14842 | N12: 19258 | O12: 5893 | P12: 9248 | Q12: 12438 | R12: 14842 | S12: 19258 | AG12: 6.8 ค่ารักษาพยาบาลอื่นๆ ต่อการเข้าพักรักษาตัวครั้งใดครั้งหนึ่ง (รวมค่ายากลับบ้าน ค่ารถพยาบาล และอื่นๆ) | AH12: 15000 | AI12: 20000 | AJ12: 30000 | AK12: 35000 | AL12: 45000
A13: 14 | B13: 475 | C13: 950 | D13: 0 | E13: 0 | F13: 0 | G13: 0 | I13: 8 | J13: 5893 | K13: 9248 | L13: 12438 | M13: 14842 | N13: 19258 | O13: 5893 | P13: 9248 | Q13: 12438 | R13: 14842 | S13: 19258 | AG13: - รับเพิ่ม 70% ของค่าใช้จ่ายส่วนที่เกินสิทธิสำหรับค่ารักษาพยาบาลอื่นๆ ในฐานะผู้ป่วยในตามเงื่อนไขของกรมธรรม์ (กรณีค่าใช้จ่ายรวมทั้งหมดไม่เกินผลประโยชน์สูงสุดของแต่ละแผน)
A14: 15 | B14: 475 | C14: 950 | D14: 0 | E14: 0 | F14: 0 | G14: 0 | I14: 9 | J14: 5893 | K14: 9248 | L14: 12438 | M14: 14842 | N14: 19258 | O14: 5893 | P14: 9248 | Q14: 12438 | R14: 14842 | S14: 19258 | AG14: 6.9 ค่าตรวจวินิจฉัยทางรังสีวิทยาและการตรวจในห้องปฎิบัติการในฐานะผู้ป่วยนอก ต่อการบาดเจ็บหรือเจ็บป่วยแต่ละครั้ง (ซึ่งเกิดขึ้นภายใน 30 วัน ก่อนหรือหลังการเข้ารักษาตัวในโรงพยาบาล) | AH14: 4000 | AI14: 6000 | AJ14: 8000 | AK14: 10000 | AL14: 14000
A15: 16 | B15: 650 | C15: 1300 | D15: 2600 | E15: 3900 | F15: 5200 | G15: 6500 | I15: 10 | J15: 5893 | K15: 9248 | L15: 12438 | M15: 14842 | N15: 19258 | O15: 5893 | P15: 9248 | Q15: 12438 | R15: 14842 | S15: 19258 | AG15: 6.10 ค่ารักษาพยาบาลฉุกเฉินขณะเป็นผู้ป่วยนอก (เนื่องจากอุบัติเหตุ) ต่อการบาดเจ็บแต่ละครั้ง | AH15: 3500 | AI15: 6000 | AJ15: 9000 | AK15: 10000 | AL15: 12000
A16: 17 | B16: 650 | C16: 1300 | D16: 2600 | E16: 3900 | F16: 5200 | G16: 6500 | I16: 11 | J16: 5354 | K16: 8401 | L16: 11299 | M16: 13483 | N16: 17495 | O16: 5354 | P16: 8401 | Q16: 11299 | R16: 13483 | S16: 17495 | AG16: 6.11 ค่ารักษาพยาบาลในฐานะผู้ป่วยนอกต่อเนื่องจากการรักษาพยาบาลในฐานะผู้ป่วยใน โดยเกิดขึ้นภายใน 30 วัน หลังออกจากโรงพยาบาลในฐานะผู้ป่วยใน | AH16: ตามเงื่อนไขของสัญญา | AI16: ตามเงื่อนไขของสัญญา | AJ16: ตามเงื่อนไขของสัญญา | AK16: ตามเงื่อนไขของสัญญา | AL16: ตามเงื่อนไขของสัญญา
A17: 18 | B17: 650 | C17: 1300 | D17: 2600 | E17: 3900 | F17: 5200 | G17: 6500 | I17: 12 | J17: 5354 | K17: 8401 | L17: 11299 | M17: 13483 | N17: 17495 | O17: 5354 | P17: 8401 | Q17: 11299 | R17: 13483 | S17: 17495 | AG17: ผลประโยชน์สูงสุด ต่อการเข้าพักรักษาตัวครั้งใดครั้งหนึ่ง | AH17: 280000 | AI17: 480000 | AJ17: 650000 | AK17: 800000 | AL17: 1100000
A18: 19 | B18: 650 | C18: 1300 | D18: 2600 | E18: 3900 | F18: 5200 | G18: 6500 | I18: 13 | J18: 5354 | K18: 8401 | L18: 11299 | M18: 13483 | N18: 17495 | O18: 5354 | P18: 8401 | Q18: 11299 | R18: 13483 | S18: 17495
A19: 20 | B19: 650 | C19: 1300 | D19: 2600 | E19: 3900 | F19: 5200 | G19: 6500 | I19: 14 | J19: 5354 | K19: 8401 | L19: 11299 | M19: 13483 | N19: 17495 | O19: 5354 | P19: 8401 | Q19: 11299 | R19: 13483 | S19: 17495
A20: 21 | B20: 650 | C20: 1300 | D20: 2600 | E20: 3900 | F20: 5200 | G20: 6500 | I20: 15 | J20: 5354 | K20: 8401 | L20: 11299 | M20: 13483 | N20: 17495 | O20: 5354 | P20: 8401 | Q20: 11299 | R20: 13483 | S20: 17495
A21: 22 | B21: 650 | C21: 1300 | D21: 2600 | E21: 3900 | F21: 5200 | G21: 6500 | I21: 16 | J21: 4237 | K21: 6648 | L21: 8942 | M21: 10670 | N21: 13845 | O21: 4622 | P21: 7253 | Q21: 9755 | R21: 11640 | S21: 15103
A22: 23 | B22: 650 | C22: 1300 | D22: 2600 | E22: 3900 | F22: 5200 | G22: 6500 | I22: 17 | J22: 4237 | K22: 6648 | L22: 8942 | M22: 10670 | N22: 13845 | O22: 4622 | P22: 7253 | Q22: 9755 | R22: 11640 | S22: 15103
A23: 24 | B23: 650 | C23: 1300 | D23: 2600 | E23: 3900 | F23: 5200 | G23: 6500 | I23: 18 | J23: 4237 | K23: 6648 | L23: 8942 | M23: 10670 | N23: 13845 | O23: 4622 | P23: 7253 | Q23: 9755 | R23: 11640 | S23: 15103
A24: 25 | B24: 650 | C24: 1300 | D24: 2600 | E24: 3900 | F24: 5200 | G24: 6500 | I24: 19 | J24: 4237 | K24: 6648 | L24: 8942 | M24: 10670 | N24: 13845 | O24: 4622 | P24: 7253 | Q24: 9755 | R24: 11640 | S24: 15103
A25: 26 | B25: 650 | C25: 1300 | D25: 2600 | E25: 3900 | F25: 5200 | G25: 6500 | I25: 20 | J25: 4237 | K25: 6648 | L25: 8942 | M25: 10670 | N25: 13845 | O25: 4622 | P25: 7253 | Q25: 9755 | R25: 11640 | S25: 15103
A26: 27 | B26: 650 | C26: 1300 | D26: 2600 | E26: 3900 | F26: 5200 | G26: 6500 | I26: 21 | J26: 3852 | K26: 6044 | L26: 8129 | M26: 9700 | N26: 12586 | O26: 5008 | P26: 7857 | Q26: 10568 | R26: 12610 | S26: 16362
A27: 28 | B27: 650 | C27: 1300 | D27: 2600 | E27: 3900 | F27: 5200 | G27: 6500 | I27: 22 | J27: 3852 | K27: 6044 | L27: 8129 | M27: 9700 | N27: 12586 | O27: 5008 | P27: 7857 | Q27: 10568 | R27: 12610 | S27: 16362
A28: 29 | B28: 650 | C28: 1300 | D28: 2600 | E28: 3900 | F28: 5200 | G28: 6500 | I28: 23 | J28: 3852 | K28: 6044 | L28: 8129 | M28: 9700 | N28: 12586 | O28: 5008 | P28: 7857 | Q28: 10568 | R28: 12610 | S28: 16362
A29: 30 | B29: 650 | C29: 1300 | D29: 2600 | E29: 3900 | F29: 5200 | G29: 6500 | I29: 24 | J29: 3852 | K29: 6044 | L29: 8129 | M29: 9700 | N29: 12586 | O29: 5008 | P29: 7857 | Q29: 10568 | R29: 12610 | S29: 16362
... A42: 43 | B42: 750 | C42: 1500 | D42: 3000 | E42: 4500 | F42: 6000 | G42: 7500 | I42: 37 | J42: 4622 | K42: 7253 | L42: 9755 | M42: 11640 | N42: 15103 | O42: 6009 | P42: 9429 | Q42: 12681 | R42: 15132 | S42: 19634
A43: 44 | B43: 750 | C43: 1500 | D43: 3000 | E43: 4500 | F43: 6000 | G43: 7500 | I43: 38 | J43: 4622 | K43: 7253 | L43: 9755 | M43: 11640 | N43: 15103 | O43: 6009 | P43: 9429 | Q43: 12681 | R43: 15132 | S43: 19634 | V43: DCI | W43: 20 | X43: DCI-20 | Y43: 2.35 | Z43: 1.92
A44: 45 | B44: 750 | C44: 1500 | D44: 3000 | E44: 4500 | F44: 6000 | G44: 7500 | I44: 39 | J44: 4622 | K44: 7253 | L44: 9755 | M44: 11640 | N44: 15103 | O44: 6009 | P44: 9429 | Q44: 12681 | R44: 15132 | S44: 19634 | V44: DCI | W44: 21 | X44: DCI-21 | Y44: 2.45 | Z44: 2.01
A45: 46 | B45: 750 | C45: 1500 | D45: 3000 | E45: 4500 | F45: 6000 | G45: 7500 | I45: 40 | J45: 4622 | K45: 7253 | L45: 9755 | M45: 11640 | N45: 15103 | O45: 6009 | P45: 9429 | Q45: 12681 | R45: 15132 | S45: 19634 | V45: DCI | W45: 22 | X45: DCI-22 | Y45: 2.54 | Z45: 2.1
A46: 47 | B46: 750 | C46: 1500 | D46: 3000 | E46: 4500 | F46: 6000 | G46: 7500 | I46: 41 | J46: 5008 | K46: 7857 | L46: 10568 | M46: 12610 | N46: 16362 | O46: 6510 | P46: 10214 | Q46: 13738 | R46: 16393 | S46: 21270 | V46: DCI | W46: 23 | X46: DCI-23 | Y46: 2.61 | Z46: 2.18
A47: 48 | B47: 750 | C47: 1500 | D47: 3000 | E47: 4500 | F47: 6000 | G47: 7500 | I47: 42 | J47: 5008 | K47: 7857 | L47: 10568 | M47: 12610 | N47: 16362 | O47: 6510 | P47: 10214 | Q47: 13738 | R47: 16393 | S47: 21270 | V47: DCI | W47: 24 | X47: DCI-24 | Y47: 2.66 | Z47: 2.24
A48: 49 | B48: 750 | C48: 1500 | D48: 3000 | E48: 4500 | F48: 6000 | G48: 7500 | I48: 43 | J48: 5008 | K48: 7857 | L48: 10568 | M48: 12610 | N48: 16362 | O48: 6510 | P48: 10214 | Q48: 13738 | R48: 16393 | S48: 21270 | V48: DCI | W48: 25 | X48: DCI-25 | Y48: 2.7 | Z48: 2.28
A49: 50 | B49: 750 | C49: 1500 | D49: 3000 | E49: 4500 | F49: 6000 | G49: 7500 | I49: 44 | J49: 5008 | K49: 7857 | L49: 10568 | M49: 12610 | N49: 16362 | O49: 6510 | P49: 10214 | Q49: 13738 | R49: 16393 | S49: 21270 | V49: DCI | W49: 26 | X49: DCI-26 | Y49: 2.77 | Z49: 2.34
A50: 51 | B50: 1000 | C50: 2000 | D50: 4000 | E50: 6000 | F50: 8000 | G50: 10000 | I50: 45 | J50: 5008 | K50: 7857 | L50: 10568 | M50: 12610 | N50: 16362 | O50: 6510 | P50: 10214 | Q50: 13738 | R50: 16393 | S50: 21270 | V50: DCI | W50: 27 | X50: DCI-27 | Y50: 2.85 | Z50: 2.4
A51: 52 | B51: 1000 | C51: 2000 | D51: 4000 | E51: 6000 | F51: 8000 | G51: 10000 | I51: 46 | J51: 5585 | K51: 8764 | L51: 11787 | M51: 14065 | N51: 18250 | O51: 7280 | P51: 11423 | Q51: 15364 | R51: 18333 | S51: 23788 | V51: DCI | W51: 28 | X51: DCI-28 | Y51: 2.97 | Z51: 2.49
A52: 53 | B52: 1000 | C52: 2000 | D52: 4000 | E52: 6000 | F52: 8000 | G52: 10000 | I52: 47 | J52: 5585 | K52: 8764 | L52: 11787 | M52: 14065 | N52: 18250 | O52: 7280 | P52: 11423 | Q52: 15364 | R52: 18333 | S52: 23788 | V52: DCI | W52: 29 | X52: DCI-29 | Y52: 3.09 | Z52: 2.6
...

Sheet Rate rider_MEX
A1: Rider Plan | B1: MEX1 | C1: MEX2 | D1: MEX3 | E1: MEX4 | F1: MEX5 | G1: MEX1 | H1: MEX2 | I1: MEX3 | J1: MEX4 | K1: MEX5
A2: Rider Class | B2: 1 | C2: 1 | D2: 1 | E2: 1 | F2: 1 | G2: 1 | H2: 1 | I2: 1 | J2: 1 | K2: 1
A3: Gender | B3: F | C3: F | D3: F | E3: F | F3: F | G3: M | H3: M | I3: M | J3: M | K3: M
A4: Rider Eff. | B4: 20210801 | C4: 20210801 | D4: 20210801 | E4: 20210801 | F4: 20210801 | G4: 20210801 | H4: 20210801 | I4: 20210801 | J4: 20210801 | K4: 20210801
B5: F-1200 | C5: F-2200 | D5: F-3200 | E5: F-4200 | F5: F-6200 | G5: M-1200 | H5: M-2200 | I5: M-3200 | J5: M-4200 | K5: M-6200
A6: 0 | B6: 25781 | C6: 40182 | D6: 54257 | E6: 0 | F6: 0 | G6: 31209 | H6: 48642 | I6: 65680 | J6: 0 | K6: 0
A7: 1 | B7: 25781 | C7: 40182 | D7: 54257 | E7: 0 | F7: 0 | G7: 29995 | H7: 46749 | I7: 63125 | J7: 0 | K7: 0
A8: 2 | B8: 25781 | C8: 40182 | D8: 54257 | E8: 0 | F8: 0 | G8: 29995 | H8: 46749 | I8: 63125 | J8: 0 | K8: 0
A9: 3 | B9: 20282 | C9: 31612 | D9: 42684 | E9: 0 | F9: 0 | G9: 23781 | H9: 37066 | I9: 50049 | J9: 0 | K9: 0
A10: 4 | B10: 14926 | C10: 23263 | D10: 31412 | E10: 0 | F10: 0 | G10: 18640 | H10: 29051 | I10: 39228 | J10: 0 | K10: 0
A11: 5 | B11: 12498 | C11: 19479 | D11: 26302 | E11: 0 | F11: 0 | G11: 14569 | H11: 22707 | I11: 30661 | J11: 0 | K11: 0
A12: 6 | B12: 10641 | C12: 16585 | D12: 22394 | E12: 0 | F12: 0 | G12: 12641 | H12: 19702 | I12: 26603 | J12: 0 | K12: 0
A13: 7 | B13: 9427 | C13: 14693 | D13: 19839 | E13: 0 | F13: 0 | G13: 9855 | H13: 15361 | I13: 20741 | J13: 0 | K13: 0
A14: 8 | B14: 7856 | C14: 12244 | D14: 16533 | E14: 0 | F14: 0 | G14: 8141 | H14: 12689 | I14: 17134 | J14: 0 | K14: 0
A15: 9 | B15: 6856 | C15: 10686 | D15: 14429 | E15: 0 | F15: 0 | G15: 6999 | H15: 10908 | I15: 14729 | J15: 0 | K15: 0
A16: 10 | B16: 5713 | C16: 8905 | D16: 12024 | E16: 0 | F16: 0 | G16: 5856 | H16: 9127 | I16: 12324 | J16: 0 | K16: 0
A17: 11 | B17: 7641 | C17: 11910 | D17: 16082 | E17: 19184 | F17: 26299 | G17: 7689 | H17: 11984 | I17: 16182 | J17: 19304 | K17: 26462
... A95: 89 | B95: 81700 | C95: 127336 | D95: 171940 | E95: 205107 | F95: 281174 | G95: 98268 | H95: 153160 | I95: 206809 | J95: 246702 | K95: 338195

Sheet iHealthy Ultra Rate
B1: Check | C1: =กรอกข้อมูล!M29 -> No
B2: Insure Age | C2: =กรอกข้อมูล!$C$5 -> 44 | D2: =IF(C2<11,"J","S") -> S | H2: เอเชีย | I2: A
B3: Gender | C3: =กรอกข้อมูล!$C$6 -> หญิง | D3: =IF(OR(C3="ชาย",C3="Male"),"M","F") -> F | H3: ทั่วโลก | I3: W
B4: แผนไอเฮลท์ตี้ อัลตร้า | C4: =กรอกข้อมูล!$M$27 -> 0 | D4: =กรอกข้อมูล!$R$37 | H4: ประเทศไทย
B5: Coverage | C5: =กรอกข้อมูล!D31 -> 0 | D5: =IFERROR(IF(C5="Full Coverage","",IF(C5="Deductible","D",IF(C5="Co-Payment","C",""))),"")
B6: Cover | C6: =กรอกข้อมูล!$M$28 -> ประเทศไทย | D6: =VLOOKUP($C6,H2:I4,2,FALSE)
B7: Key | D7: =TRIM("MHP"&D5&D4&D2&D6) -> MHPS | E7: =D7&"-"&D3 -> MHPS-F
B8: Premium | D8: =IF(C1="OK",HLOOKUP(E7,$B$9:$BU$111,C2+5,0),0) -> 0
A9: Key | B9: MHP1J-F | C9: MHP1S-F | D9: MHP2J-F | E9: MHP2S-F | F9: MHP3S-F | G9: MHP4S-F | H9: MHP5S-F | I9: MHP5SA-F | J9: MHP5SW-F | K9: MHP6S-F | L9: MHP6SA-F | M9: MHP6SW-F | N9: MHP1J-M | O9: MHP1S-M | P9: MHP2J-M | Q9: MHP2S-M | R9: MHP3S-M | S9: MHP4S-M | T9: MHP5S-M | U9: MHP5SA-M | V9: MHP5SW-M | W9: MHP6S-M | X9: MHP6SA-M | Y9: MHP6SW-M | Z9: MHPC1J-F | AA9: MHPC1S-F | AB9: MHPC2J-F | AC9: MHPC2S-F | AD9: MHPC3S-F | AE9: MHPC4S-F | AF9: MHPC5S-F | AG9: MHPCSA-F | AH9: MHPCSW-F | AI9: MHPC6S-F | AJ9: MHPCSA-F | AK9: MHPCSW-F | AL9: MHPC1J-M | AM9: MHPC1S-M | AN9: MHPC2J-M | AO9: MHPC2S-M | AP9: MHPC3S-M | AQ9: MHPC4S-M | AR9: MHPC5S-M | AS9: MHPCSA-M | AT9: MHPCSW-M | AU9: MHPC6S-M | AV9: MHPCSA-M | AW9: MHPCSW-M | AX9: MHPD1J-F | AY9: MHPD1S-F | AZ9: MHPD2J-F | BA9: MHPD2S-F | BB9: MHPD3S-F | BC9: MHPD4S-F | BD9: MHPD5S-F | BE9: MHPDSA-F | BF9: MHPDSW-F | BG9: MHPD6S-F | BH9: MHPDSA-F | BI9: MHPDSW-F | BJ9: MHPD1J-M | BK9: MHPD1S-M | BL9: MHPD2J-M | BM9: MHPD2S-M | BN9: MHPD3S-M | BO9: MHPD4S-M | BP9: MHPD5S-M | BQ9: MHPDSA-M | BR9: MHPDSW-M | BS9: MHPD6S-M | BT9: MHPDSA-M | BU9: MHPDSW-M
A10: Plan code | B10: MHP1J | C10: MHP1S | D10: MHP2J | E10: MHP2S | F10: MHP3S | G10: MHP4S | H10: MHP5S | I10: MHP5SA | J10: MHP5SW | K10: MHP6S | L10: MHP6SA | M10: MHP6SW | N10: MHP1J | O10: MHP1S | P10: MHP2J | Q10: MHP2S | R10: MHP3S | S10: MHP4S | T10: MHP5S | U10: MHP5SA | V10: MHP5SW | W10: MHP6S | X10: MHP6SA | Y10: MHP6SW | Z10: =LEFT(Z9,6) -> MHPC1J | AA10: =LEFT(AA9,6) -> MHPC1S | AB10: =LEFT(AB9,6) -> MHPC2J | AC10: =LEFT(AC9,6) -> MHPC2S | AD10: =LEFT(AD9,6) -> MHPC3S | AE10: =LEFT(AE9,6) -> MHPC4S | AF10: =LEFT(AF9,6) -> MHPC5S | AG10: =LEFT(AG9,6) -> MHPCSA | ... BU10: =LEFT(BU9,6) -> MHPDSW
A11: Class | B11: 1 | C11: 1 | D11: 1 | E11: 1 | F11: 1 | G11: 1 | H11: 1 | I11: 1 | J11: 1 | K11: 1 | L11: 1 | M11: 1 | N11: 1 | O11: 1 | P11: 1 | Q11: 1 | R11: 1 | S11: 1 | T11: 1 | U11: 1 | V11: 1 | W11: 1 | X11: 1 | Y11: 1 | Z11: 1 | AA11: 1 | AB11: 1 | AC11: 1 | AD11: 1 | AE11: 1 | AF11: 1 | AG11: 1 | AH11: 1 | AI11: 1 | AJ11: 1 | AK11: 1 | AL11: 1 | AM11: 1 | AN11: 1 | AO11: 1 | AP11: 1 | AQ11: 1 | AR11: 1 | AS11: 1 | AT11: 1 | AU11: 1 | AV11: 1 | AW11: 1 | AX11: 1 | AY11: 1 | AZ11: 1 | BA11: 1 | BB11: 1 | BC11: 1 | BD11: 1 | BE11: 1 | BF11: 1 | BG11: 1 | BH11: 1 | BI11: 1 | BJ11: 1 | BK11: 1 | BL11: 1 | BM11: 1 | BN11: 1 | BO11: 1 | BP11: 1 | BQ11: 1 | BR11: 1 | BS11: 1 | BT11: 1 | BU11: 1
A12: Gender | B12: F | C12: F | D12: F | E12: F | F12: F | G12: F | H12: F | I12: F | J12: F | K12: F | L12: F | M12: F | N12: M | O12: M | P12: M | Q12: M | R12: M | S12: M | T12: M | U12: M | V12: M | W12: M | X12: M | Y12: M | Z12: F | AA12: F | AB12: F | AC12: F | AD12: F | AE12: F | AF12: F | AG12: F | AH12: F | AI12: F | AJ12: F | AK12: F | AL12: M | AM12: M | AN12: M | AO12: M | AP12: M | AQ12: M | AR12: M | AS12: M | AT12: M | AU12: M | AV12: M | AW12: M | AX12: F | AY12: F | AZ12: F | BA12: F | BB12: F | BC12: F | BD12: F | BE12: F | BF12: F | BG12: F | BH12: F | BI12: F | BJ12: M | BK12: M | BL12: M | BM12: M | BN12: M | BO12: M | BP12: M | BQ12: M | BR12: M | BS12: M | BT12: M | BU12: M
A13: 0 | B13: 0 | C13: 0 | D13: 0 | E13: 0 | F13: 0 | G13: 0 | H13: 0 | I13: 0 | J13: 0 | K13: 0 | L13: 0 | M13: 0 | N13: 0 | O13: 0 | P13: 0 | Q13: 0 | R13: 0 | S13: 0 | T13: 0 | U13: 0 | V13: 0 | W13: 0 | X13: 0 | Y13: 0 | Z13: 0 | AA13: 0 | AB13: 0 | AC13: 0 | AD13: 0 | AE13: 0 | AF13: 0 | AG13: - | AH13: - | AI13: 0 | AJ13: - | AK13: - | AL13: 0 | AM13: 0 | AN13: 0 | AO13: 0 | AP13: 0 | AQ13: 0 | AR13: 0 | AS13: - | AT13: - | AU13: 0 | AV13: - | AW13: - | AX13: 0 | AY13: 0 | AZ13: 0 | BA13: 0 | BB13: 0 | BC13: 0 | BD13: 0 | BE13: - | BF13: - | BG13: 0 | BH13: - | BI13: - | BJ13: 0 | BK13: 0 | BL13: 0 | BM13: 0 | BN13: 0 | BO13: 0 | BP13: 0 | BQ13: - | BR13: - | BS13: 0 | BT13: - | BU13: -
A14: 1 | B14: 0 | C14: 0 | D14: 0 | E14: 0 | F14: 0 | G14: 0 | H14: 0 | I14: 0 | J14: 0 | K14: 0 | L14: 0 | M14: 0 | N14: 0 | O14: 0 | P14: 0 | Q14: 0 | R14: 0 | S14: 0 | T14: 0 | U14: 0 | V14: 0 | W14: 0 | X14: 0 | Y14: 0 | Z14: 0 | AA14: 0 | AB14: 0 | AC14: 0 | AD14: 0 | AE14: 0 | AF14: 0 | AG14: - | AH14: - | AI14: 0 | AJ14: - | AK14: - | AL14: 0 | AM14: 0 | AN14: 0 | AO14: 0 | AP14: 0 | AQ14: 0 | AR14: 0 | AS14: - | AT14: - | AU14: 0 | AV14: - | AW14: - | AX14: 0 | AY14: 0 | AZ14: 0 | BA14: 0 | BB14: 0 | BC14: 0 | BD14: 0 | BE14: - | BF14: - | BG14: 0 | BH14: - | BI14: - | BJ14: 0 | BK14: 0 | BL14: 0 | BM14: 0 | BN14: 0 | BO14: 0 | BP14: 0 | BQ14: - | BR14: - | BS14: 0 | BT14: - | BU14: -
A15: 2 | B15: 0 | C15: 0 | D15: 0 | E15: 0 | F15: 0 | G15: 0 | H15: 0 | I15: 0 | J15: 0 | K15: 0 | L15: 0 | M15: 0 | N15: 0 | O15: 0 | P15: 0 | Q15: 0 | R15: 0 | S15: 0 | T15: 0 | U15: 0 | V15: 0 | W15: 0 | X15: 0 | Y15: 0 | Z15: 0 | AA15: 0 | AB15: 0 | AC15: 0 | AD15: 0 | AE15: 0 | AF15: 0 | AG15: - | AH15: - | AI15: 0 | AJ15: - | AK15: - | AL15: 0 | AM15: 0 | AN15: 0 | AO15: 0 | AP15: 0 | AQ15: 0 | AR15: 0 | AS15: - | AT15: - | AU15: 0 | AV15: - | AW15: - | AX15: 0 | AY15: 0 | AZ15: 0 | BA15: 0 | BB15: 0 | BC15: 0 | BD15: 0 | BE15: - | BF15: - | BG15: 0 | BH15: - | BI15: - | BJ15: 0 | BK15: 0 | BL15: 0 | BM15: 0 | BN15: 0 | BO15: 0 | BP15: 0 | BQ15: - | BR15: - | BS15: 0 | BT15: - | BU15: -
A16: 3 | B16: 0 | C16: 0 | D16: 0 | E16: 0 | F16: 0 | G16: 0 | H16: 0 | I16: 0 | J16: 0 | K16: 0 | L16: 0 | M16: 0 | N16: 0 | O16: 0 | P16: 0 | Q16: 0 | R16: 0 | S16: 0 | T16: 0 | U16: 0 | V16: 0 | W16: 0 | X16: 0 | Y16: 0 | Z16: 0 | AA16: 0 | AB16: 0 | AC16: 0 | AD16: 0 | AE16: 0 | AF16: 0 | AG16: - | AH16: - | AI16: 0 | AJ16: - | AK16: - | AL16: 0 | AM16: 0 | AN16: 0 | AO16: 0 | AP16: 0 | AQ16: 0 | AR16: 0 | AS16: - | AT16: - | AU16: 0 | AV16: - | AW16: - | AX16: 0 | AY16: 0 | AZ16: 0 | BA16: 0 | BB16: 0 | BC16: 0 | BD16: 0 | BE16: - | BF16: - | BG16: 0 | BH16: - | BI16: - | BJ16: 0 | BK16: 0 | BL16: 0 | BM16: 0 | BN16: 0 | BO16: 0 | BP16: 0 | BQ16: - | BR16: - | BS16: 0 | BT16: - | BU16: -
A17: 4 | B17: 0 | C17: 0 | D17: 0 | E17: 0 | F17: 0 | G17: 0 | H17: 0 | I17: 0 | J17: 0 | K17: 0 | L17: 0 | M17: 0 | N17: 0 | O17: 0 | P17: 0 | Q17: 0 | R17: 0 | S17: 0 | T17: 0 | U17: 0 | V17: 0 | W17: 0 | X17: 0 | Y17: 0 | Z17: 0 | AA17: 0 | AB17: 0 | AC17: 0 | AD17: 0 | AE17: 0 | AF17: 0 | AG17: - | AH17: - | AI17: 0 | AJ17: - | AK17: - | AL17: 0 | AM17: 0 | AN17: 0 | AO17: 0 | AP17: 0 | AQ17: 0 | AR17: 0 | AS17: - | AT17: - | AU17: 0 | AV17: - | AW17: - | AX17: 0 | AY17: 0 | AZ17: 0 | BA17: 0 | BB17: 0 | BC17: 0 | BD17: 0 | BE17: - | BF17: - | BG17: 0 | BH17: - | BI17: - | BJ17: 0 | BK17: 0 | BL17: 0 | BM17: 0 | BN17: 0 | BO17: 0 | BP17: 0 | BQ17: - | BR17: - | BS17: 0 | BT17: - | BU17: -
A18: 5 | B18: 0 | C18: 0 | D18: 0 | E18: 0 | F18: 0 | G18: 0 | H18: 0 | I18: 0 | J18: 0 | K18: 0 | L18: 0 | M18: 0 | N18: 0 | O18: 0 | P18: 0 | Q18: 0 | R18: 0 | S18: 0 | T18: 0 | U18: 0 | V18: 0 | W18: 0 | X18: 0 | Y18: 0 | Z18: 0 | AA18: 0 | AB18: 0 | AC18: 0 | AD18: 0 | AE18: 0 | AF18: 0 | AG18: - | AH18: - | AI18: 0 | AJ18: - | AK18: - | AL18: 0 | AM18: 0 | AN18: 0 | AO18: 0 | AP18: 0 | AQ18: 0 | AR18: 0 | AS18: - | AT18: - | AU18: 0 | AV18: - | AW18: - | AX18: 0 | AY18: 0 | AZ18: 0 | BA18: 0 | BB18: 0 | BC18: 0 | BD18: 0 | BE18: - | BF18: - | BG18: 0 | BH18: - | BI18: - | BJ18: 0 | BK18: 0 | BL18: 0 | BM18: 0 | BN18: 0 | BO18: 0 | BP18: 0 | BQ18: - | BR18: - | BS18: 0 | BT18: - | BU18: -
A19: 6 | B19: 40100 | C19: 0 | D19: 47800 | E19: 0 | F19: 0 | G19: 0 | H19: 0 | I19: 0 | J19: 0 | K19: 0 | L19: 0 | M19: 0 | N19: 46700 | O19: 0 | P19: 55700 | Q19: 0 | R19: 0 | S19: 0 | T19: 0 | U19: 0 | V19: 0 | W19: 0 | X19: 0 | Y19: 0 | Z19: 32000 | AA19: 0 | AB19: 38200 | AC19: 0 | AD19: 0 | AE19: 0 | AF19: 0 | AG19: - | AH19: - | AI19: 0 | AJ19: - | AK19: - | AL19: 37300 | AM19: 0 | AN19: 44500 | AO19: 0 | AP19: 0 | AQ19: 0 | AR19: 0 | AS19: - | AT19: - | AU19: 0 | AV19: - | AW19: - | AX19: 29300 | AY19: 0 | AZ19: 35700 | BA19: 0 | BB19: 0 | BC19: 0 | BD19: 0 | BE19: - | BF19: - | BG19: 0 | BH19: - | BI19: - | BJ19: 34100 | BK19: 0 | BL19: 41600 | BM19: 0 | BN19: 0 | BO19: 0 | BP19: 0 | BQ19: - | BR19: - | BS19: 0 | BT19: - | BU19: -
A20: 7 | B20: 32800 | C20: 0 | D20: 39200 | E20: 0 | F20: 0 | G20: 0 | H20: 0 | I20: 0 | J20: 0 | K20: 0 | L20: 0 | M20: 0 | N20: 38300 | O20: 0 | P20: 45700 | Q20: 0 | R20: 0 | S20: 0 | T20: 0 | U20: 0 | V20: 0 | W20: 0 | X20: 0 | Y20: 0 | Z20: 26200 | AA20: 0 | AB20: 31300 | AC20: 0 | AD20: 0 | AE20: 0 | AF20: 0 | AG20: - | AH20: - | AI20: 0 | AJ20: - | AK20: - | AL20: 30600 | AM20: 0 | AN20: 36500 | AO20: 0 | AP20: 0 | AQ20: 0 | AR20: 0 | AS20: - | AT20: - | AU20: 0 | AV20: - | AW20: - | AX20: 24000 | AY20: 0 | AZ20: 29300 | BA20: 0 | BB20: 0 | BC20: 0 | BD20: 0 | BE20: - | BF20: - | BG20: 0 | BH20: - | BI20: - | BJ20: 28000 | BK20: 0 | BL20: 34100 | BM20: 0 | BN20: 0 | BO20: 0 | BP20: 0 | BQ20: - | BR20: - | BS20: 0 | BT20: - | BU20: -
A21: 8 | B21: 29400 | C21: 0 | D21: 35100 | E21: 0 | F21: 0 | G21: 0 | H21: 0 | I21: 0 | J21: 0 | K21: 0 | L21: 0 | M21: 0 | N21: 32300 | O21: 0 | P21: 38600 | Q21: 0 | R21: 0 | S21: 0 | T21: 0 | U21: 0 | V21: 0 | W21: 0 | X21: 0 | Y21: 0 | Z21: 23500 | AA21: 0 | AB21: 28000 | AC21: 0 | AD21: 0 | AE21: 0 | AF21: 0 | AG21: - | AH21: - | AI21: 0 | AJ21: - | AK21: - | AL21: 25800 | AM21: 0 | AN21: 30800 | AO21: 0 | AP21: 0 | AQ21: 0 | AR21: 0 | AS21: - | AT21: - | AU21: 0 | AV21: - | AW21: - | AX21: 21500 | AY21: 0 | AZ21: 26200 | BA21: 0 | BB21: 0 | BC21: 0 | BD21: 0 | BE21: - | BF21: - | BG21: 0 | BH21: - | BI21: - | BJ21: 23600 | BK21: 0 | BL21: 28800 | BM21: 0 | BN21: 0 | BO21: 0 | BP21: 0 | BQ21: - | BR21: - | BS21: 0 | BT21: - | BU21: -
A22: 9 | B22: 26000 | C22: 0 | D22: 31100 | E22: 0 | F22: 0 | G22: 0 | H22: 0 | I22: 0 | J22: 0 | K22: 0 | L22: 0 | M22: 0 | N22: 26400 | O22: 0 | P22: 31500 | Q22: 0 | R22: 0 | S22: 0 | T22: 0 | U22: 0 | V22: 0 | W22: 0 | X22: 0 | Y22: 0 | Z22: 20800 | AA22: 0 | AB22: 24800 | AC22: 0 | AD22: 0 | AE22: 0 | AF22: 0 | AG22: - | AH22: - | AI22: 0 | AJ22: - | AK22: - | AL22: 21100 | AM22: 0 | AN22: 25200 | AO22: 0 | AP22: 0 | AQ22: 0 | AR22: 0 | AS22: - | AT22: - | AU22: 0 | AV22: - | AW22: - | AX22: 19000 | AY22: 0 | AZ22: 23200 | BA22: 0 | BB22: 0 | BC22: 0 | BD22: 0 | BE22: - | BF22: - | BG22: 0 | BH22: - | BI22: - | BJ22: 19300 | BK22: 0 | BL22: 23600 | BM22: 0 | BN22: 0 | BO22: 0 | BP22: 0 | BQ22: - | BR22: - | BS22: 0 | BT22: - | BU22: -
A23: 10 | B23: 23400 | C23: 0 | D23: 28000 | E23: 0 | F23: 0 | G23: 0 | H23: 0 | I23: 0 | J23: 0 | K23: 0 | L23: 0 | M23: 0 | N23: 23900 | O23: 0 | P23: 28500 | Q23: 0 | R23: 0 | S23: 0 | T23: 0 | U23: 0 | V23: 0 | W23: 0 | X23: 0 | Y23: 0 | Z23: 18700 | AA23: 0 | AB23: 22400 | AC23: 0 | AD23: 0 | AE23: 0 | AF23: 0 | AG23: - | AH23: - | AI23: 0 | AJ23: - | AK23: - | AL23: 19100 | AM23: 0 | AN23: 22800 | AO23: 0 | AP23: 0 | AQ23: 0 | AR23: 0 | AS23: - | AT23: - | AU23: 0 | AV23: - | AW23: - | AX23: 17200 | AY23: 0 | AZ23: 20900 | BA23: 0 | BB23: 0 | BC23: 0 | BD23: 0 | BE23: - | BF23: - | BG23: 0 | BH23: - | BI23: - | BJ23: 17500 | BK23: 0 | BL23: 21300 | BM23: 0 | BN23: 0 | BO23: 0 | BP23: 0 | BQ23: - | BR23: - | BS23: 0 | BT23: - | BU23: -
A24: 11 | B24: 23200 | C24: 23200 | D24: 27600 | E24: 27600 | F24: 39900 | G24: 51300 | H24: 85500 | I24: 152300 | J24: 295600 | K24: 134000 | L24: 222300 | M24: 443000 | N24: 23700 | O24: 23700 | P24: 28300 | Q24: 28300 | R24: 41800 | S24: 53900 | T24: 87800 | U24: 156400 | V24: 303500 | W24: 148300 | X24: 246000 | Y24: 490200 | Z24: 18500 | AA24: 18500 | AB24: 22000 | AC24: 22000 | AD24: 31900 | AE24: 41000 | AF24: 68400 | AG24: - | AH24: - | AI24: 107200 | AJ24: - | AK24: - | AL24: 18900 | AM24: 18900 | AN24: 22600 | AO24: 22600 | AP24: 33400 | AQ24: 43100 | AR24: 70200 | AS24: - | AT24: - | AU24: 118600 | AV24: - | AW24: - | AX24: 17000 | AY24: 17000 | AZ24: 20700 | BA24: 20700 | BB24: 28700 | BC24: 37100 | BD24: 69900 | BE24: - | BF24: - | BG24: 105700 | BH24: - | BI24: - | BJ24: 17400 | BK24: 17400 | BL24: 21200 | BM24: 21200 | BN24: 30300 | BO24: 39400 | BP24: 73000 | BQ24: - | BR24: - | BS24: 120400 | BT24: - | BU24: -
... A102: 89 | B102: 204100 | C102: 204100 | D102: 242600 | E102: 242600 | F102: 325100 | G102: 412900 | H102: 557700 | I102: 993200 | J102: 1926900 | K102: 815800 | L102: 1353500 | M102: 2696700 | N102: 244300 | O102: 244300 | P102: 290400 | Q102: 290400 | R102: 387600 | S102: 491800 | T102: 620700 | U102: 1105400 | V102: 2144600 | W102: 804800 | X102: 1335200 | Y102: 2660400 | Z102: 163200 | AA102: 163200 | AB102: 194000 | AC102: 194000 | AD102: 260000 | AE102: 330300 | AF102: 446100 | AG102: - | AH102: - | AI102: 652600 | AJ102: - | AK102: - | AL102: 195400 | AM102: 195400 | AN102: 232300 | AO102: 232300 | AP102: 310000 | AQ102: 393400 | AR102: 496500 | AS102: - | AT102: - | AU102: 643800 | AV102: - | AW102: - | AX102: 174500 | AY102: 174500 | AZ102: 207600 | BA102: 207600 | BB102: 249800 | BC102: 308400 | BD102: 422800 | BE102: - | BF102: - | BG102: 555500 | BH102: - | BI102: - | BJ102: 208500 | BK102: 208500 | BL102: 247500 | BM102: 247500 | BN102: 295600 | BO102: 362900 | BP102: 455000 | BQ102: - | BR102: - | BS102: 518700 | BT102: - | BU102: -
A103: 90 | B103: 214600 | C103: 214600 | D103: 253800 | E103: 253800 | F103: 337600 | G103: 426900 | H103: 574900 | I103: - | J103: - | K103: 834600 | L103: - | M103: - | N103: 252300 | O103: 252300 | P103: 298200 | Q103: 298200 | R103: 394900 | S103: 498500 | T103: 627200 | U103: - | V103: - | W103: 811100 | X103: - | Y103: - | Z103: 171600 | AA103: 171600 | AB103: 203000 | AC103: 203000 | AD103: 270000 | AE103: 341500 | AF103: 459900 | AG103: - | AH103: - | AI103: 667600 | AJ103: - | AK103: - | AL103: 201800 | AM103: 201800 | AN103: 238500 | AO103: 238500 | AP103: 315900 | AQ103: 398800 | AR103: 501700 | AS103: - | AT103: - | AU103: 648800 | AV103: - | AW103: - | AX103: 178800 | AY103: 178800 | AZ103: 212900 | BA103: 212900 | BB103: 256100 | BC103: 316400 | BD103: 433600 | BE103: - | BF103: - | BG103: 565600 | BH103: - | BI103: - | BJ103: 211500 | BK103: 211500 | BL103: 251200 | BM103: 251200 | BN103: 300000 | BO103: 368500 | BP103: 461400 | BQ103: - | BR103: - | BS103: 524900 | BT103: - | BU103: -
A104: 91 | B104: 225200 | C104: 225200 | D104: 265000 | E104: 265000 | F104: 350200 | G104: 440900 | H104: 592100 | I104: - | J104: - | K104: 853300 | L104: - | M104: - | N104: 260300 | O104: 260300 | P104: 305900 | Q104: 305900 | R104: 402200 | S104: 505300 | T104: 633600 | U104: - | V104: - | W104: 817500 | X104: - | Y104: - | Z104: 180100 | AA104: 180100 | AB104: 212000 | AC104: 212000 | AD104: 280100 | AE104: 352700 | AF104: 473600 | AG104: - | AH104: - | AI104: 682600 | AJ104: - | AK104: - | AL104: 208200 | AM104: 208200 | AN104: 244700 | AO104: 244700 | AP104: 321700 | AQ104: 404200 | AR104: 506800 | AS104: - | AT104: - | AU104: 654000 | AV104: - | AW104: - | AX104: 183100 | AY104: 183100 | AZ104: 218100 | BA104: 218100 | BB104: 262400 | BC104: 324400 | BD104: 444300 | BE104: - | BF104: - | BG104: 575800 | BH104: - | BI104: - | BJ104: 214600 | BK104: 214600 | BL104: 254900 | BM104: 254900 | BN104: 304500 | BO104: 374200 | BP104: 467900 | BQ104: - | BR104: - | BS104: 531100 | BT104: - | BU104: -
A105: 92 | B105: 235900 | C105: 235900 | D105: 276900 | E105: 276900 | F105: 364300 | G105: 457500 | H105: 612800 | I105: - | J105: - | K105: 876400 | L105: - | M105: - | N105: 270900 | O105: 270900 | P105: 317300 | Q105: 317300 | R105: 415100 | S105: 519900 | T105: 650100 | U105: - | V105: - | W105: 835800 | X105: - | Y105: - | Z105: 188700 | AA105: 188700 | AB105: 221500 | AC105: 221500 | AD105: 291400 | AE105: 366000 | AF105: 490200 | AG105: - | AH105: - | AI105: 701100 | AJ105: - | AK105: - | AL105: 216700 | AM105: 216700 | AN105: 253800 | AO105: 253800 | AP105: 332000 | AQ105: 415900 | AR105: 520000 | AS105: - | AT105: - | AU105: 668600 | AV105: - | AW105: - | AX105: 187400 | AY105: 187400 | AZ105: 223400 | BA105: 223400 | BB105: 268800 | BC105: 332400 | BD105: 455100 | BE105: - | BF105: - | BG105: 586000 | BH105: - | BI105: - | BJ105: 217600 | BK105: 217600 | BL105: 258600 | BM105: 258600 | BN105: 309000 | BO105: 379800 | BP105: 474300 | BQ105: - | BR105: - | BS105: 537300 | BT105: - | BU105: -
A106: 93 | B106: 246600 | C106: 246600 | D106: 288800 | E106: 288800 | F106: 378400 | G106: 474100 | H106: 633600 | I106: - | J106: - | K106: 899500 | L106: - | M106: - | N106: 281500 | O106: 281500 | P106: 328700 | Q106: 328700 | R106: 428000 | S106: 534600 | T106: 666600 | U106: - | V106: - | W106: 854000 | X106: - | Y106: - | Z106: 197200 | AA106: 197200 | AB106: 231000 | AC106: 231000 | AD106: 302700 | AE106: 379200 | AF106: 506800 | AG106: - | AH106: - | AI106: 719600 | AJ106: - | AK106: - | AL106: 225200 | AM106: 225200 | AN106: 262900 | AO106: 262900 | AP106: 342400 | AQ106: 427600 | AR106: 533200 | AS106: - | AT106: - | AU106: 683200 | AV106: - | AW106: - | AX106: 191700 | AY106: 191700 | AZ106: 228600 | BA106: 228600 | BB106: 275100 | BC106: 340300 | BD106: 465800 | BE106: - | BF106: - | BG106: 596200 | BH106: - | BI106: - | BJ106: 220600 | BK106: 220600 | BL106: 262300 | BM106: 262300 | BN106: 313400 | BO106: 385400 | BP106: 480800 | BQ106: - | BR106: - | BS106: 543600 | BT106: - | BU106: -
A107: 94 | B107: 254400 | C107: 254400 | D107: 298000 | E107: 298000 | F107: 390500 | G107: 489400 | H107: 654500 | I107: - | J107: - | K107: 923300 | L107: - | M107: - | N107: 287200 | O107: 287200 | P107: 335600 | Q107: 335600 | R107: 437100 | S107: 546200 | T107: 680400 | U107: - | V107: - | W107: 870000 | X107: - | Y107: - | Z107: 203500 | AA107: 203500 | AB107: 238400 | AC107: 238400 | AD107: 312400 | AE107: 391500 | AF107: 523600 | AG107: - | AH107: - | AI107: 738600 | AJ107: - | AK107: - | AL107: 229700 | AM107: 229700 | AN107: 268400 | AO107: 268400 | AP107: 349600 | AQ107: 436900 | AR107: 544300 | AS107: - | AT107: - | AU107: 696000 | AV107: - | AW107: - | AX107: 197300 | AY107: 197300 | AZ107: 235500 | BA107: 235500 | BB107: 283300 | BC107: 350800 | BD107: 480200 | BE107: - | BF107: - | BG107: 609700 | BH107: - | BI107: - | BJ107: 224800 | BK107: 224800 | BL107: 267500 | BM107: 267500 | BN107: 319600 | BO107: 393300 | BP107: 489800 | BQ107: - | BR107: - | BS107: 552200 | BT107: - | BU107: -
A108: 95 | B108: 262100 | C108: 262100 | D108: 307200 | E108: 307200 | F108: 402600 | G108: 504800 | H108: 675400 | I108: - | J108: - | K108: 947100 | L108: - | M108: - | N108: 293000 | O108: 293000 | P108: 342500 | Q108: 342500 | R108: 446200 | S108: 557700 | T108: 694200 | U108: - | V108: - | W108: 885900 | X108: - | Y108: - | Z108: 209600 | AA108: 209600 | AB108: 245700 | AC108: 245700 | AD108: 322000 | AE108: 403800 | AF108: 540300 | AG108: - | AH108: - | AI108: 757600 | AJ108: - | AK108: - | AL108: 234400 | AM108: 234400 | AN108: 274000 | AO108: 274000 | AP108: 356900 | AQ108: 446100 | AR108: 555300 | AS108: - | AT108: - | AU108: 708700 | AV108: - | AW108: - | AX108: 202900 | AY108: 202900 | AZ108: 242400 | BA108: 242400 | BB108: 291600 | BC108: 361200 | BD108: 494500 | BE108: - | BF108: - | BG108: 623300 | BH108: - | BI108: - | BJ108: 229100 | BK108: 229100 | BL108: 272600 | BM108: 272600 | BN108: 325800 | BO108: 401100 | BP108: 498700 | BQ108: - | BR108: - | BS108: 560900 | BT108: - | BU108: -
A109: 96 | B109: 269800 | C109: 269800 | D109: 316400 | E109: 316400 | F109: 414700 | G109: 520200 | H109: 696300 | I109: - | J109: - | K109: 970900 | L109: - | M109: - | N109: 298800 | O109: 298800 | P109: 349400 | Q109: 349400 | R109: 455300 | S109: 569200 | T109: 708000 | U109: - | V109: - | W109: 901800 | X109: - | Y109: - | Z109: 215800 | AA109: 215800 | AB109: 253100 | AC109: 253100 | AD109: 331700 | AE109: 416100 | AF109: 557000 | AG109: - | AH109: - | AI109: 776700 | AJ109: - | AK109: - | AL109: 239000 | AM109: 239000 | AN109: 279500 | AO109: 279500 | AP109: 364200 | AQ109: 455300 | AR109: 566400 | AS109: - | AT109: - | AU109: 721400 | AV109: - | AW109: - | AX109: 208600 | AY109: 208600 | AZ109: 249200 | BA109: 249200 | BB109: 299800 | BC109: 371700 | BD109: 508900 | BE109: - | BF109: - | BG109: 636900 | BH109: - | BI109: - | BJ109: 233300 | BK109: 233300 | BL109: 277800 | BM109: 277800 | BN109: 332000 | BO109: 408900 | BP109: 507700 | BQ109: - | BR109: - | BS109: 569500 | BT109: - | BU109: -
A110: 97 | B110: 277500 | C110: 277500 | D110: 325600 | E110: 325600 | F110: 426800 | G110: 535500 | H110: 717200 | I110: - | J110: - | K110: 994600 | L110: - | M110: - | N110: 304600 | O110: 304600 | P110: 356300 | Q110: 356300 | R110: 464400 | S110: 580700 | T110: 721700 | U110: - | V110: - | W110: 917700 | X110: - | Y110: - | Z110: 222000 | AA110: 222000 | AB110: 260400 | AC110: 260400 | AD110: 341400 | AE110: 428400 | AF110: 573700 | AG110: - | AH110: - | AI110: 795600 | AJ110: - | AK110: - | AL110: 243600 | AM110: 243600 | AN110: 285000 | AO110: 285000 | AP110: 371500 | AQ110: 464500 | AR110: 577300 | AS110: - | AT110: - | AU110: 734100 | AV110: - | AW110: - | AX110: 214200 | AY110: 214200 | AZ110: 256100 | BA110: 256100 | BB110: 308100 | BC110: 382100 | BD110: 523200 | BE110: - | BF110: - | BG110: 650500 | BH110: - | BI110: - | BJ110: 237500 | BK110: 237500 | BL110: 282900 | BM110: 282900 | BN110: 338200 | BO110: 416800 | BP110: 516700 | BQ110: - | BR110: - | BS110: 578200 | BT110: - | BU110: -
A111: 98 | B111: 285200 | C111: 285200 | D111: 334900 | E111: 334900 | F111: 439000 | G111: 550900 | H111: 738100 | I111: - | J111: - | K111: 1018400 | L111: - | M111: - | N111: 310400 | O111: 310400 | P111: 363200 | Q111: 363200 | R111: 473500 | S111: 592300 | T111: 735500 | U111: - | V111: - | W111: 933700 | X111: - | Y111: - | Z111: 228100 | AA111: 228100 | AB111: 267900 | AC111: 267900 | AD111: 351200 | AE111: 440700 | AF111: 590400 | AG111: - | AH111: - | AI111: 814700 | AJ111: - | AK111: - | AL111: 248300 | AM111: 248300 | AN111: 290500 | AO111: 290500 | AP111: 378800 | AQ111: 473800 | AR111: 588400 | AS111: - | AT111: - | AU111: 746900 | AV111: - | AW111: - | AX111: 219800 | AY111: 219800 | AZ111: 263000 | BA111: 263000 | BB111: 316300 | BC111: 392500 | BD111: 537600 | BE111: - | BF111: - | BG111: 664000 | BH111: - | BI111: - | BJ111: 241700 | BK111: 241700 | BL111: 288100 | BM111: 288100 | BN111: 344400 | BO111: 424600 | BP111: 525600 | BQ111: - | BR111: - | BS111: 586900 | BT111: - | BU111: -

Sheet Login
E2: LOGIN
K3: di6'wmp
D4: Username : | F4: =IF(E4="","",IF(#REF!=0,"คุณใส่ User Name ไม่ถูกต้อง",""))
D5: Password : | F5: =IF(E4="","",IF(F4<>"","กรุณาใส่ User Name ให้ถูกต้อง",IF(E5="","กรุณาใส่ Password",IF(#REF!="NO","คุณใส่ Password ไม่ถูกต้อง",""))))
E6: =IF(E10="Login Complete","","กรุณากรอก Username / Password เพื่อเริ่มใช้งาน") -> #REF!
D8: Broker Name : | E8: =IF(AND(F4="",F5=""),VLOOKUP($E4,#REF!,2,FALSE),"N/A") -> #REF!
D9: Password
D10: Check password | E10: =IF(#REF!="YES","Login Complete","") -> #REF!

Sheet Data support
A1: Product Name | B1: WPTPD | C1: WPTPDCI
A2: Official Product Name TH : | B2: สัญญาเพิ่มเติมผลประโยชน์ยกเว้นเบี้ยประกันภัยสัญญาหลัก (คุ้มครองการทุพพลภาพถาวรสิ้นเชิง) | C2: สัญญาเพิ่มเติมผลประโยชน์ยกเว้นเบี้ยประกันภัยสัญญาหลัก (คุ้มครองการทุพพลภาพถาวรสิ้นเชิงและโรคร้ายแรง)
A3: Official Product Name EN : | B3: Waiver of Basic Premium Rider (Cover for Total and permanent disability) | C3: Waiver of Basic Premium Rider (Cover for Total and permanent disability and Critical Illness) | E3: 1.1.1 Plan Code:
A4: Marketing name TH : | B4: N/A | C4: N/A
A5: Marketing name EN : | B5: N/A | C5: N/A | E5: WP Plancode:
A6: Product Type : | B6: Rider | C6: Rider
A7: Par / Non-Par | B7: Non-Par | C7: Non-Par
A8: Product Code : | B8: WPTPD (TBC) | C8: WPTPDCI (TBC) | E8: Product WP | F8: Plan code | G8: System Plan Code
A9: Product Category | B9: Protection | C9: Protection | E9: Waiver of Premium Rider (Total Permanent Disability) | F9: WPTPD | G9: WPTPDxx
A10: Policy term / | B10: Minimum of | C10: Minimum of | E10: Waiver of Premium Rider (Total Permanent Disability and Critical Illness) | F10: WPTPDCI | G10: WPTCIxx
A11: Coverage period: | B11: · PPP(4) of basic plan | C11: · PPP(4) of basic plan
B12: · 80 – issued age | C12: · 80 – issued age | E12: System plan code will be align with the waive periods and premium rate provide in Appendix 2
A13: Premium payment term: | B13: Minimum of | C13: Minimum of | E13: Example plancode:
B14: · PPP(4) of basic plan | C14: · PPP(4) of basic plan | E14: WPTPD02, WPTPD03, … , WPTPD25, WPTPD55, WPTPD60, WPTPD85, WPTPD99
B15: · 80 – issued age | C15: · 80 – issued age | E15: WPTCI02, WPTCI03, … , WPTCI25, WPTCI55, WPTCI60, WPTCI85, WPTCI99
A16: Period to waive premium | B16: Until end of PPP of basic plan | C16: Until end of PPP of basic plan
A17: Type of product development: | B17: Restyling Product | C17: Restyling Product
A18: (New product / Restyling / Repricing)
A31: Product Specification for PB Rider (PBFP, PBBP, PBFS, PBBS)
B53: Period to waive premium | C53: Until end of PPP of basic plan | D53: WP เอาใช้ดุระยะเวลา waive เบี้ย

Sheet Rate CI 123
A1: RLPLAN | B1: Plancode | C1: RLOCLS | D1: RLCLS | E1: RLSEX | F1: KEY | G1: RLL00 | H1: RLL01 | I1: RLL02 | J1: RLL03 | K1: RLL04 | L1: RLL05 | M1: RLL06 | N1: RLL07 | O1: RLL08 | P1: RLL09 | Q1: RLL10 | R1: RLL11 | S1: RLL12 | T1: RLL13 | U1: RLL14 | V1: RLL15 | W1: RLL16 | X1: RLL17 | Y1: RLL18 | Z1: RLL19 | AA1: RLL20 | AB1: RLL21 | AC1: RLL22 | AD1: RLL23 | AE1: RLL24 | AF1: RLL25 | AG1: RLL26 | AH1: RLL27 | AI1: RLL28 | AJ1: RLL29 | AK1: RLL30 | AL1: RLL31 | AM1: RLL32 | AN1: RLL33 | AO1: RLL34 | AP1: RLL35 | AQ1: RLL36 | AR1: RLL37 | AS1: RLL38 | AT1: RLL39 | AU1: RLL40 | AV1: RLL41 | AW1: RLL42 | AX1: RLL43 | AY1: RLL44 | AZ1: RLL45 | BA1: RLL46 | BB1: RLL47 | BC1: RLL48 | BD1: RLL49 | BE1: RLL50 | BF1: RLL51 | BG1: RLL52 | BH1: RLL53 | BI1: RLL54 | BJ1: RLL55 | BK1: RLL56 | BL1: RLL57 | BM1: RLL58 | BN1: RLL59 | BO1: RLL60 | BP1: RLL61 | BQ1: RLL62 | BR1: RLL63 | BS1: RLL64 | BT1: RLL65 | BU1: RLL66 | BV1: RLL67 | BW1: RLL68 | BX1: RLL69 | BY1: RLL70 | BZ1: RLL71 | CA1: RLL72 | CB1: RLL73 | CC1: RLL74 | CD1: RLL75 | CE1: RLL76 | CF1: RLL77 | CG1: RLL78 | CH1: RLL79 | CI1: RLL80 | CJ1: RLL81 | CK1: RLL82 | CL1: RLL83 | CM1: RLL84 | CN1: RLL85 | CO1: RLL86 | CP1: RLL87 | CQ1: RLL88 | CR1: RLL89 | CS1: RLL90 | CT1: RLL91 | CU1: RLL92 | CV1: RLL93 | CW1: RLL94 | CX1: RLL95 | CY1: RLL96 | CZ1: RLL97 | DA1: RLL98 | DB1: RLL99 | DC1: RLW00 | DD1: RLW01 | DE1: RLW02 | DF1: RLW03 | DG1: RLW04 | DH1: RLW05 | DI1: RLW06 | DJ1: RLW07 | DK1: RLW08 | DL1: RLW09 | DM1: RLW10 | DN1: RLW11 | DO1: RLW12 | DP1: RLW13 | DQ1: RLW14 | DR1: RLW15 | DS1: RLW16 | DT1: RLW17 | DU1: RLW18 | DV1: RLW19 | DW1: RLW20 | DX1: RLW21 | DY1: RLW22 | DZ1: RLW23 | EA1: RLW24 | EB1: RLW25 | EC1: RLW26 | ED1: RLW27 | EE1: RLW28 | EF1: RLW29 | EG1: RLW30 | EH1: RLW31 | EI1: RLW32 | EJ1: RLW33 | EK1: RLW34 | EL1: RLW35 | EM1: RLW36 | EN1: RLW37 | EO1: RLW38 | EP1: RLW39 | EQ1: RLW40 | ER1: RLW41 | ES1: RLW42 | ET1: RLW43 | EU1: RLW44 | EV1: RLW45 | EW1: RLW46 | EX1: RLW47 | EY1: RLW48 | EZ1: RLW49 | FA1: RLW50 | FB1: RLW51 | FC1: RLW52 | FD1: RLW53 | FE1: RLW54 | FF1: RLW55 | FG1: RLW56 | FH1: RLW57 | FI1: RLW58 | FJ1: RLW59 | FK1: RLW60 | FL1: RLW61 | FM1: RLW62 | FN1: RLW63 | FO1: RLW64 | FP1: RLW65 | FQ1: RLW66 | FR1: RLW67 | FS1: RLW68 | FT1: RLW69 | FU1: RLW70 | FV1: RLW71 | FW1: RLW72 | FX1: RLW73 | FY1: RLW74 | FZ1: RLW75 | GA1: RLW76 | GB1: RLW77 | GC1: RLW78 | GD1: RLW79 | GE1: RLW80 | GF1: RLW81 | GG1: RLW82 | GH1: RLW83 | GI1: RLW84 | GJ1: RLW85 | GK1: RLW86 | GL1: RLW87 | GM1: RLW88 | GN1: RLW89 | GO1: RLW90 | GP1: RLW91 | GQ1: RLW92 | GR1: RLW93 | GS1: RLW94 | GT1: RLW95 | GU1: RLW96 | GV1: RLW97 | GW1: RLW98 | GX1: RLW99
A2: Major CI | B2: CIES3 | D2: 1 | E2: F | F2: =A2&"-"&E2 -> Major CI-F | G2: 1.41 | H2: 1.38 | I2: 1.37 | J2: 1.35 | K2: 1.34 | L2: 1.32 | M2: 1.3 | N2: 1.28 | O2: 1.26 | P2: 1.29 | Q2: 1.41 | R2: 1.61 | S2: 1.77 | T2: 1.65 | U2: 1.53 | V2: 1.43 | W2: 1.4 | X2: 1.37 | Y2: 1.4 | Z2: 1.43 | AA2: 1.6 | AB2: 1.69 | AC2: 1.78 | AD2: 1.88 | AE2: 1.97 | AF2: 1.97 | AG2: 2 | AH2: 2.1 | AI2: 2.48 | AJ2: 2.53 | AK2: 2.55 | AL2: 2.58 | AM2: 2.61 | AN2: 3.03 | AO2: 3.51 | AP2: 3.2 | AQ2: 3.62 | AR2: 4.07 | AS2: 4.55 | AT2: 5.05 | AU2: 5.02 | AV2: 5.64 | AW2: 6.32 | AX2: 7.04 | AY2: 7.17 | AZ2: 7.58 | BA2: 8.22 | BB2: 8.93 | BC2: 9.71 | BD2: 10.01 | BE2: 10.62 | BF2: 12.62 | BG2: 13.25 | BH2: 14.31 | BI2: 15.45 | BJ2: 17.66 | BK2: 20.52 | BL2: 22.64 | BM2: 24.47 | BN2: 25.2 | BO2: 25.93 | BP2: 26.66 | BQ2: 27.39 | BR2: 29.42 | BS2: 31.77 | BT2: 32.5 | BU2: 34.74 | BV2: 37.21 | BW2: 39.33 | BX2: 41.68 | BY2: 41.93 | BZ2: 44.4 | CA2: 47.05 | CB2: 50.1 | CC2: 53.39 | CD2: 62.25 | CE2: 67.27 | CF2: 72.97 | CG2: 78.6 | CH2: 84.76 | CI2: 91.49 | CJ2: 98.86 | CK2: 106.92 | CL2: 115.26 | CM2: 124.32 | CN2: 134.21 | CO2: 143.89 | CP2: 155.29 | CQ2: 168.13 | CR2: 182.29 | CS2: 197.93 | CT2: 214.28 | CU2: 232.53 | CV2: 252.34 | CW2: 273.69 | CX2: 297.04 | CY2: 322.46 | CZ2: 350.07 | DA2: 552.62 | DB2: 0
